Workbook

Sheet Loan Input Parameters
A1: VEHICLE LOAN INPUT PARAMETERS
A3: Client | B3: Sean Van Wyk
A4: Transaction number | B4: ZAETC123456789
A6: Vehicle Type (New/Demo/Used) | B6: New
A8: Final invoice price | B8: 500000
A9: Deposit value | B9: 0
A10: Principal debt (before initiation fees to be financed) | B10: =B8-B9 -> 500000
A12: Initiation fees to be financed | B12: 1207.5
A13: Principal debt (after initiation fees to be financed) | B13: =SUM(B10:B12) -> 501207.5
A15: Annual interest rate offered | B15: 0.11
A16: Term of the loan (in months) | B16: 72
A17: Repayments in advance or arrears | B17: Arrears
A18: Monthly instalment (without balloon repayment) | B18: =IF(B17="Advance",PMT(B15/12,B16,-$B$13,0,1),PMT(B15/12,B16,-$B$13,0,0)) -> 9540.0232
A20: Ballon payment value | B20: 170000
A21: Monthly instalment (with balloon payment) | B21: =PMT(B15/12,B16,-$B$13,B20,IF(B17="Advance",1,0)) -> 7862.5631 | C21: =B20/'Depreciation Parameters'!B3 -> 0.34
A23: Monthly service charge | B23: 69
A24: Total monthly repayment | B24: =B21+B23 -> 7931.5631
A26: Payment start date | B26: 45200
A28: Product | B28: TRAFICC TOP-UP (G305)
A29: Product Option | B29: TOP-UP
A30: Monthly Premium | B30: =VLOOKUP(B28&B29,template!$D:$F,2,FALSE)+(B8*VLOOKUP(B28&B29,template!$D:$F,3,FALSE)) -> 310
A32: Depreciation Model Standard or Override: | B32: Override
A33: Depreciation Model: | B33: Standard | C33: Override
A34: Year 1 depreciation % | B34: {=IF(B33="Overide",'Depreciation Parameters'!#REF!,IF('Loan Input Parameters'!B6="New",'Depreciation Parameters'!$B$4:$B$9,IF('Loan Input Parameters'!B6="Demo",'Depreciation Parameters'!$C$4:$C$9,IF('Loan Input Parameters'!B6="Used",'Depreciation Parameters'!$D$4:$D$9))))} -> 0.23 | C34: 0.22
A35: Year 2 depreciation % | B35: 0.15 | C35: 0.18
A36: Year 3 depreciation % | B36: 0.11 | C36: 0.15
A37: Year 4 depreciation % | B37: 0.11 | C37: 0.13
A38: Year 5 depreciation % | B38: 0.11 | C38: 0.09
A39: Year 6 depreciation % | B39: 0.1 | C39: 0.06
A41: Underlying Insurance Excess % | B41: 0
A42: Underlying Minimum Excess Rand Value | B42: 0
A45: All values include VAT

Sheet Loan Payment Schedule
A1: LOAN PAYMENT SCHEDULE
A3: Instalment number | B3: Date | C3: Opening balance | D3: Loan Instalment due | E3: Interest charged | F3: Administration fee | G3: Capital repayment | H3: Capital balance | I3: % of original Principle Debt
A4: 1 | B4: =EOMONTH('Loan Input Parameters'!B26,0) -> 45230 | C4: ='Loan Input Parameters'!B13 -> 501207.5 | D4: =IF(A4<'Loan Input Parameters'!$B$16,'Loan Input Parameters'!$B$24,IF(A4='Loan Input Parameters'!$B$16,'Loan Input Parameters'!$B$24+'Loan Input Parameters'!$B$20,0)) -> 7931.5631 | E4: =IF('Loan Input Parameters'!$B$17="Advance",0,C4*'Loan Input Parameters'!$B$15/12) -> 4594.4021 | F4: =IF(A4<='Loan Input Parameters'!$B$16,'Loan Input Parameters'!$B$23,0) -> 69 | G4: =D4-E4-F4 -> 3268.161 | H4: =C4-G4 -> 497939.34 | I4: =H4/'Loan Input Parameters'!$B$13 -> 0.99347943
A5: 2 | B5: =EOMONTH(B4,1) -> 45260 | C5: =IF(ROUND(H4,0)>0,H4,0) -> 497939.34 | D5: =IF(A5<'Loan Input Parameters'!$B$16,'Loan Input Parameters'!$B$24,IF(A5='Loan Input Parameters'!$B$16,'Loan Input Parameters'!$B$24+'Loan Input Parameters'!$B$20,0)) -> 7931.5631 | E5: =C5*'Loan Input Parameters'!$B$15/12 -> 4564.4439 | F5: =IF(A5<='Loan Input Parameters'!$B$16,'Loan Input Parameters'!$B$23,0) -> 69 | G5: =D5-E5-F5 -> 3298.1191 | H5: =C5-G5 -> 494641.22 | I5: =H5/'Loan Input Parameters'!$B$13 -> 0.98689908
A6: 3 | B6: =EOMONTH(B5,1) -> 45291 | C6: =IF(ROUND(H5,0)>0,H5,0) -> 494641.22 | D6: =IF(A6<'Loan Input Parameters'!$B$16,'Loan Input Parameters'!$B$24,IF(A6='Loan Input Parameters'!$B$16,'Loan Input Parameters'!$B$24+'Loan Input Parameters'!$B$20,0)) -> 7931.5631 | E6: =C6*'Loan Input Parameters'!$B$15/12 -> 4534.2112 | F6: =IF(A6<='Loan Input Parameters'!$B$16,'Loan Input Parameters'!$B$23,0) -> 69 | G6: =D6-E6-F6 -> 3328.3519 | H6: =C6-G6 -> 491312.87 | I6: =H6/'Loan Input Parameters'!$B$13 -> 0.98025841
A7: 4 | B7: =EOMONTH(B6,1) -> 45322 | C7: =IF(ROUND(H6,0)>0,H6,0) -> 491312.87 | D7: =IF(A7<'Loan Input Parameters'!$B$16,'Loan Input Parameters'!$B$24,IF(A7='Loan Input Parameters'!$B$16,'Loan Input Parameters'!$B$24+'Loan Input Parameters'!$B$20,0)) -> 7931.5631 | E7: =C7*'Loan Input Parameters'!$B$15/12 -> 4503.7013 | F7: =IF(A7<='Loan Input Parameters'!$B$16,'Loan Input Parameters'!$B$23,0) -> 69 | G7: =D7-E7-F7 -> 3358.8618 | H7: =C7-G7 -> 487954.01 | I7: =H7/'Loan Input Parameters'!$B$13 -> 0.97355687
A8: 5 | B8: =EOMONTH(B7,1) -> 45351 | C8: =IF(ROUND(H7,0)>0,H7,0) -> 487954.01 | D8: =IF(A8<'Loan Input Parameters'!$B$16,'Loan Input Parameters'!$B$24,IF(A8='Loan Input Parameters'!$B$16,'Loan Input Parameters'!$B$24+'Loan Input Parameters'!$B$20,0)) -> 7931.5631 | E8: =C8*'Loan Input Parameters'!$B$15/12 -> 4472.9117 | F8: =IF(A8<='Loan Input Parameters'!$B$16,'Loan Input Parameters'!$B$23,0) -> 69 | G8: =D8-E8-F8 -> 3389.6513 | H8: =C8-G8 -> 484564.35 | I8: =H8/'Loan Input Parameters'!$B$13 -> 0.9667939
A9: 6 | B9: =EOMONTH(B8,1) -> 45382 | C9: =IF(ROUND(H8,0)>0,H8,0) -> 484564.35 | D9: =IF(A9<'Loan Input Parameters'!$B$16,'Loan Input Parameters'!$B$24,IF(A9='Loan Input Parameters'!$B$16,'Loan Input Parameters'!$B$24+'Loan Input Parameters'!$B$20,0)) -> 7931.5631 | E9: =C9*'Loan Input Parameters'!$B$15/12 -> 4441.8399 | F9: =IF(A9<='Loan Input Parameters'!$B$16,'Loan Input Parameters'!$B$23,0) -> 69 | G9: =D9-E9-F9 -> 3420.7231 | H9: =C9-G9 -> 481143.63 | I9: =H9/'Loan Input Parameters'!$B$13 -> 0.95996894
A10: 7 | B10: =EOMONTH(B9,1) -> 45412 | C10: =IF(ROUND(H9,0)>0,H9,0) -> 481143.63 | D10: =IF(A10<'Loan Input Parameters'!$B$16,'Loan Input Parameters'!$B$24,IF(A10='Loan Input Parameters'!$B$16,'Loan Input Parameters'!$B$24+'Loan Input Parameters'!$B$20,0)) -> 7931.5631 | E10: =C10*'Loan Input Parameters'!$B$15/12 -> 4410.4833 | F10: =IF(A10<='Loan Input Parameters'!$B$16,'Loan Input Parameters'!$B$23,0) -> 69 | G10: =D10-E10-F10 -> 3452.0798 | H10: =C10-G10 -> 477691.55 | I10: =H10/'Loan Input Parameters'!$B$13 -> 0.95308141
A11: 8 | B11: =EOMONTH(B10,1) -> 45443 | C11: =IF(ROUND(H10,0)>0,H10,0) -> 477691.55 | D11: =IF(A11<'Loan Input Parameters'!$B$16,'Loan Input Parameters'!$B$24,IF(A11='Loan Input Parameters'!$B$16,'Loan Input Parameters'!$B$24+'Loan Input Parameters'!$B$20,0)) -> 7931.5631 | E11: =C11*'Loan Input Parameters'!$B$15/12 -> 4378.8392 | F11: =IF(A11<='Loan Input Parameters'!$B$16,'Loan Input Parameters'!$B$23,0) -> 69 | G11: =D11-E11-F11 -> 3483.7238 | H11: =C11-G11 -> 474207.83 | I11: =H11/'Loan Input Parameters'!$B$13 -> 0.94613075
A12: 9 | B12: =EOMONTH(B11,1) -> 45473 | C12: =IF(ROUND(H11,0)>0,H11,0) -> 474207.83 | D12: =IF(A12<'Loan Input Parameters'!$B$16,'Loan Input Parameters'!$B$24,IF(A12='Loan Input Parameters'!$B$16,'Loan Input Parameters'!$B$24+'Loan Input Parameters'!$B$20,0)) -> 7931.5631 | E12: =C12*'Loan Input Parameters'!$B$15/12 -> 4346.9051 | F12: =IF(A12<='Loan Input Parameters'!$B$16,'Loan Input Parameters'!$B$23,0) -> 69 | G12: =D12-E12-F12 -> 3515.658 | H12: =C12-G12 -> 470692.17 | I12: =H12/'Loan Input Parameters'!$B$13 -> 0.93911637
A13: 10 | B13: =EOMONTH(B12,1) -> 45504 | C13: =IF(ROUND(H12,0)>0,H12,0) -> 470692.17 | D13: =IF(A13<'Loan Input Parameters'!$B$16,'Loan Input Parameters'!$B$24,IF(A13='Loan Input Parameters'!$B$16,'Loan Input Parameters'!$B$24+'Loan Input Parameters'!$B$20,0)) -> 7931.5631 | E13: =C13*'Loan Input Parameters'!$B$15/12 -> 4314.6782 | F13: =IF(A13<='Loan Input Parameters'!$B$16,'Loan Input Parameters'!$B$23,0) -> 69 | G13: =D13-E13-F13 -> 3547.8848 | H13: =C13-G13 -> 467144.29 | I13: =H13/'Loan Input Parameters'!$B$13 -> 0.9320377
A14: 11 | B14: =EOMONTH(B13,1) -> 45535 | C14: =IF(ROUND(H13,0)>0,H13,0) -> 467144.29 | D14: =IF(A14<'Loan Input Parameters'!$B$16,'Loan Input Parameters'!$B$24,IF(A14='Loan Input Parameters'!$B$16,'Loan Input Parameters'!$B$24+'Loan Input Parameters'!$B$20,0)) -> 7931.5631 | E14: =C14*'Loan Input Parameters'!$B$15/12 -> 4282.1559 | F14: =IF(A14<='Loan Input Parameters'!$B$16,'Loan Input Parameters'!$B$23,0) -> 69 | G14: =D14-E14-F14 -> 3580.4071 | H14: =C14-G14 -> 463563.88 | I14: =H14/'Loan Input Parameters'!$B$13 -> 0.92489414
A15: 12 | B15: =EOMONTH(B14,1) -> 45565 | C15: =IF(ROUND(H14,0)>0,H14,0) -> 463563.88 | D15: =IF(A15<'Loan Input Parameters'!$B$16,'Loan Input Parameters'!$B$24,IF(A15='Loan Input Parameters'!$B$16,'Loan Input Parameters'!$B$24+'Loan Input Parameters'!$B$20,0)) -> 7931.5631 | E15: =C15*'Loan Input Parameters'!$B$15/12 -> 4249.3356 | F15: =IF(A15<='Loan Input Parameters'!$B$16,'Loan Input Parameters'!$B$23,0) -> 69 | G15: =D15-E15-F15 -> 3613.2275 | H15: =C15-G15 -> 459950.65 | I15: =H15/'Loan Input Parameters'!$B$13 -> 0.91768509
A16: 13 | B16: =EOMONTH(B15,1) -> 45596 | C16: =IF(ROUND(H15,0)>0,H15,0) -> 459950.65 | D16: =IF(A16<'Loan Input Parameters'!$B$16,'Loan Input Parameters'!$B$24,IF(A16='Loan Input Parameters'!$B$16,'Loan Input Parameters'!$B$24+'Loan Input Parameters'!$B$20,0)) -> 7931.5631 | E16: =C16*'Loan Input Parameters'!$B$15/12 -> 4216.2143 | F16: =IF(A16<='Loan Input Parameters'!$B$16,'Loan Input Parameters'!$B$23,0) -> 69 | G16: =D16-E16-F16 -> 3646.3488 | H16: =C16-G16 -> 456304.3 | I16: =H16/'Loan Input Parameters'!$B$13 -> 0.91040996
... A99: 96 | B99: =EOMONTH(B98,1) -> 48121 | C99: =IF(ROUND(H98,0)>0,H98,0) -> 0 | D99: =IF(A99<'Loan Input Parameters'!$B$16,'Loan Input Parameters'!$B$24,IF(A99='Loan Input Parameters'!$B$16,'Loan Input Parameters'!$B$24+'Loan Input Parameters'!$B$20,0)) -> 0 | E99: =C99*'Loan Input Parameters'!$B$15/12 -> 0 | F99: =IF(A99<='Loan Input Parameters'!$B$16,'Loan Input Parameters'!$B$23,0) -> 0 | G99: =D99-E99-F99 -> 0 | H99: =C99-G99 -> 0 | I99: =H99/'Loan Input Parameters'!$B$13 -> 0

Sheet Loan Payment Summary
A1: LOAN PAYMENT SUMMARY
A3: FULL HISTORY
A5: Total capital paid | B5: =SUM('Loan Payment Schedule'!G4:G75) -> 501207.5
A6: Total interest paid | B6: =SUM('Loan Payment Schedule'!E4:E75) -> 234897.04
A7: Total loan repayments | B7: =SUM('Loan Payment Schedule'!D4:D75) -> 741072.54
A9: PERIODIC REVIEW
A11: Review month | B11: 36
A13: Total capital paid | B13: =SUMIF('Loan Payment Schedule'!$A$4:$A$75,"<="&$B$11,'Loan Payment Schedule'!$G$4:$G$75) -> 138645.6
A14: Total interest paid | B14: =SUMIF('Loan Payment Schedule'!$A$4:$A$75,"<="&$B$11,'Loan Payment Schedule'!$E$4:$E$75) -> 144406.67
A15: Total loan repayments | B15: =SUMIF('Loan Payment Schedule'!$A$4:$A$75,"<="&$B$11,'Loan Payment Schedule'!$D$4:$D$75) -> 285536.27
A17: Total capital outstanding | B17: =VLOOKUP(B11,'Loan Payment Schedule'!$A$4:$H$75,8,0) -> 362561.9

Sheet Shortfall Illustration
A1: ILLUSTRATION OF POTENTIAL SHORTFALL
A3: Instalment number | B3: Date | C3: Opening balance | D3: Loan Instalment due | E3: Interest charged | F3: Administration fee | G3: Capital repayment | H3: Capital balance | I3: % of original Principle Debt | J3: % depreciation | K3: Market Value | L3: Insurance Excess (Based on Market Value) | M3: Market Value less Excess | N3: Illustration of Shortfall Benefit | O3: Potential Loyalty Bonus | P3: Shortfall Benefit Plus Loyalty Bonus
A4: =IFERROR(IF(1<='Loan Input Parameters'!$B$16,1,"-"),0) -> 1 | B4: =EOMONTH('Loan Input Parameters'!B26,0) -> 45230 | C4: ='Loan Input Parameters'!B13 -> 501207.5 | D4: =IF(A4<'Loan Input Parameters'!$B$16,'Loan Input Parameters'!$B$24,IF(A4='Loan Input Parameters'!$B$16,'Loan Input Parameters'!$B$24+'Loan Input Parameters'!$B$20,0)) -> 7931.5631 | E4: =IF('Loan Input Parameters'!$B$17="Advance",0,C4*'Loan Input Parameters'!$B$15/12) -> 4594.4021 | F4: =IF(A4<='Loan Input Parameters'!$B$16,'Loan Input Parameters'!$B$23,0) -> 69 | G4: =IF($A4<'Loan Input Parameters'!$B$16,D4-E4-F4,"0.00") -> 3268.161 | H4: =C4-G4 -> 497939.34 | I4: =H4/'Loan Input Parameters'!$B$13 -> 0.99347943 | J4: =IF('Loan Input Parameters'!$B$32="Overide",'Loan Input Parameters'!$C$34,'Loan Input Parameters'!$B$34) -> 0.23 | K4: =_xlfn.LET(_xlpm.DEPRECIATION,IF('Loan Input Parameters'!$B$6="Used",0.08,0.05), IF( MONTH($B4)=1, 'Depreciation Parameters'!$B$3*(1-(35%*J4)+_xlpm.DEPRECIATION),'Depreciation Parameters'!$B$3*(1-_xlpm.DEPRECIATION))) -> 475000 | L4: =IF(K4*'Loan Input Parameters'!$B$41<'Loan Input Parameters'!$B$42,'Loan Input Parameters'!$B$42,K4*'Loan Input Parameters'!$B$41) -> 0 | M4: =K4-L4 -> 475000 | N4: =H4-(K4-L4) -> 22939.339 | O4: =IF('Loan Input Parameters'!$B$8*3%<=4000,4000,IF('Loan Input Parameters'!$B$8*3%>=18000,18000,'Loan Input Parameters'!$B$8*3%)) -> 15000 | P4: =IF(N4<0,O4,N4+O4) -> 37939.339
A5: =A4+1 -> 2 | B5: =EOMONTH(B4,1) -> 45260 | C5: =IF(ROUND(H4,0)>0,H4,0) -> 497939.34 | D5: =IF(A5<'Loan Input Parameters'!$B$16,'Loan Input Parameters'!$B$24,IF(A5='Loan Input Parameters'!$B$16,'Loan Input Parameters'!$B$24+'Loan Input Parameters'!$B$20,0)) -> 7931.5631 | E5: =IF($A5<'Loan Input Parameters'!$B$16,C5*'Loan Input Parameters'!$B$15/12,"0.00") -> 4564.4439 | F5: =IF(A5<='Loan Input Parameters'!$B$16,'Loan Input Parameters'!$B$23,0) -> 69 | G5: =IF($A5<'Loan Input Parameters'!$B$16,D5-E5-F5,"0.00") -> 3298.1191 | H5: =IF($A5<'Loan Input Parameters'!$B$16,C5-G5,"0.00") -> 494641.22 | I5: =H5/'Loan Input Parameters'!$B$13 -> 0.98689908 | J5: =J4 -> 0.23 | K5: {=IF( AND(MONTH($B5)=1,SUMPRODUCT(--(MONTH($B$4:B5)=1))=1), K4*(1-22%*J5), IF( AND(MONTH($B5)=1,SUMPRODUCT(--(MONTH($B$4:B5)=1))=2), K4*(1-20%*J5), IF($A5<13,K4*(1-(J5*4%)), IF($A5<25,K4*(1-(J5*5%)),K4*(1-J5/12) ) ) ))} -> 470630 | L5: =IF(K5*'Loan Input Parameters'!$B$41<'Loan Input Parameters'!$B$42,'Loan Input Parameters'!$B$42,K5*'Loan Input Parameters'!$B$41) -> 0 | M5: =K5-L5 -> 470630 | N5: =H5-(K5-L5) -> 24011.22 | O5: =IF('Loan Input Parameters'!$B$8*3%<=4000,4000,IF('Loan Input Parameters'!$B$8*3%>=18000,18000,'Loan Input Parameters'!$B$8*3%)) -> 15000 | P5: =IF(N5<0,O5,N5+O5) -> 39011.22
A6: =A5+1 -> 3 | B6: =EOMONTH(B5,1) -> 45291 | C6: =IF(ROUND(H5,0)>0,H5,0) -> 494641.22 | D6: =IF(A6<'Loan Input Parameters'!$B$16,'Loan Input Parameters'!$B$24,IF(A6='Loan Input Parameters'!$B$16,'Loan Input Parameters'!$B$24+'Loan Input Parameters'!$B$20,0)) -> 7931.5631 | E6: =IF($A6<'Loan Input Parameters'!$B$16,C6*'Loan Input Parameters'!$B$15/12,"0.00") -> 4534.2112 | F6: =IF(A6<='Loan Input Parameters'!$B$16,'Loan Input Parameters'!$B$23,0) -> 69 | G6: =IF($A6<'Loan Input Parameters'!$B$16,D6-E6-F6,"0.00") -> 3328.3519 | H6: =IF($A6<'Loan Input Parameters'!$B$16,C6-G6,"0.00") -> 491312.87 | I6: =H6/'Loan Input Parameters'!$B$13 -> 0.98025841 | J6: =J5 -> 0.23 | K6: {=IF( AND(MONTH($B6)=1,SUMPRODUCT(--(MONTH($B$4:B6)=1))=1), K5*(1-22%*J6), IF( AND(MONTH($B6)=1,SUMPRODUCT(--(MONTH($B$4:B6)=1))=2), K5*(1-20%*J6), IF($A6<13,K5*(1-(J6*4%)), IF($A6<25,K5*(1-(J6*5%)),K5*(1-J6/12) ) ) ))} -> 466300.2 | L6: =IF(K6*'Loan Input Parameters'!$B$41<'Loan Input Parameters'!$B$42,'Loan Input Parameters'!$B$42,K6*'Loan Input Parameters'!$B$41) -> 0 | M6: =K6-L6 -> 466300.2 | N6: =H6-(K6-L6) -> 25012.664 | O6: =IF('Loan Input Parameters'!$B$8*3%<=4000,4000,IF('Loan Input Parameters'!$B$8*3%>=18000,18000,'Loan Input Parameters'!$B$8*3%)) -> 15000 | P6: =IF(N6<0,O6,N6+O6) -> 40012.664
A7: =A6+1 -> 4 | B7: =EOMONTH(B6,1) -> 45322 | C7: =IF(ROUND(H6,0)>0,H6,0) -> 491312.87 | D7: =IF(A7<'Loan Input Parameters'!$B$16,'Loan Input Parameters'!$B$24,IF(A7='Loan Input Parameters'!$B$16,'Loan Input Parameters'!$B$24+'Loan Input Parameters'!$B$20,0)) -> 7931.5631 | E7: =IF($A7<'Loan Input Parameters'!$B$16,C7*'Loan Input Parameters'!$B$15/12,"0.00") -> 4503.7013 | F7: =IF(A7<='Loan Input Parameters'!$B$16,'Loan Input Parameters'!$B$23,0) -> 69 | G7: =IF($A7<'Loan Input Parameters'!$B$16,D7-E7-F7,"0.00") -> 3358.8618 | H7: =IF($A7<'Loan Input Parameters'!$B$16,C7-G7,"0.00") -> 487954.01 | I7: =H7/'Loan Input Parameters'!$B$13 -> 0.97355687 | J7: =J6 -> 0.23 | K7: {=IF( AND(MONTH($B7)=1,SUMPRODUCT(--(MONTH($B$4:B7)=1))=1), K6*(1-22%*J7), IF( AND(MONTH($B7)=1,SUMPRODUCT(--(MONTH($B$4:B7)=1))=2), K6*(1-20%*J7), IF($A7<13,K6*(1-(J7*4%)), IF($A7<25,K6*(1-(J7*5%)),K6*(1-J7/12) ) ) ))} -> 442705.41 | L7: =IF(K7*'Loan Input Parameters'!$B$41<'Loan Input Parameters'!$B$42,'Loan Input Parameters'!$B$42,K7*'Loan Input Parameters'!$B$41) -> 0 | M7: =K7-L7 -> 442705.41 | N7: =H7-(K7-L7) -> 45248.593 | O7: =IF('Loan Input Parameters'!$B$8*3%<=4000,4000,IF('Loan Input Parameters'!$B$8*3%>=18000,18000,'Loan Input Parameters'!$B$8*3%)) -> 15000 | P7: =IF(N7<0,O7,N7+O7) -> 60248.593
A8: =A7+1 -> 5 | B8: =EOMONTH(B7,1) -> 45351 | C8: =IF(ROUND(H7,0)>0,H7,0) -> 487954.01 | D8: =IF(A8<'Loan Input Parameters'!$B$16,'Loan Input Parameters'!$B$24,IF(A8='Loan Input Parameters'!$B$16,'Loan Input Parameters'!$B$24+'Loan Input Parameters'!$B$20,0)) -> 7931.5631 | E8: =IF($A8<'Loan Input Parameters'!$B$16,C8*'Loan Input Parameters'!$B$15/12,"0.00") -> 4472.9117 | F8: =IF(A8<='Loan Input Parameters'!$B$16,'Loan Input Parameters'!$B$23,0) -> 69 | G8: =IF($A8<'Loan Input Parameters'!$B$16,D8-E8-F8,"0.00") -> 3389.6513 | H8: =IF($A8<'Loan Input Parameters'!$B$16,C8-G8,"0.00") -> 484564.35 | I8: =H8/'Loan Input Parameters'!$B$13 -> 0.9667939 | J8: =J7 -> 0.23 | K8: {=IF( AND(MONTH($B8)=1,SUMPRODUCT(--(MONTH($B$4:B8)=1))=1), K7*(1-22%*J8), IF( AND(MONTH($B8)=1,SUMPRODUCT(--(MONTH($B$4:B8)=1))=2), K7*(1-20%*J8), IF($A8<13,K7*(1-(J8*4%)), IF($A8<25,K7*(1-(J8*5%)),K7*(1-J8/12) ) ) ))} -> 438632.52 | L8: =IF(K8*'Loan Input Parameters'!$B$41<'Loan Input Parameters'!$B$42,'Loan Input Parameters'!$B$42,K8*'Loan Input Parameters'!$B$41) -> 0 | M8: =K8-L8 -> 438632.52 | N8: =H8-(K8-L8) -> 45931.831 | O8: =IF('Loan Input Parameters'!$B$8*3%<=4000,4000,IF('Loan Input Parameters'!$B$8*3%>=18000,18000,'Loan Input Parameters'!$B$8*3%)) -> 15000 | P8: =IF(N8<0,O8,N8+O8) -> 60931.831
A9: =A8+1 -> 6 | B9: =EOMONTH(B8,1) -> 45382 | C9: =IF(ROUND(H8,0)>0,H8,0) -> 484564.35 | D9: =IF(A9<'Loan Input Parameters'!$B$16,'Loan Input Parameters'!$B$24,IF(A9='Loan Input Parameters'!$B$16,'Loan Input Parameters'!$B$24+'Loan Input Parameters'!$B$20,0)) -> 7931.5631 | E9: =IF($A9<'Loan Input Parameters'!$B$16,C9*'Loan Input Parameters'!$B$15/12,"0.00") -> 4441.8399 | F9: =IF(A9<='Loan Input Parameters'!$B$16,'Loan Input Parameters'!$B$23,0) -> 69 | G9: =IF($A9<'Loan Input Parameters'!$B$16,D9-E9-F9,"0.00") -> 3420.7231 | H9: =IF($A9<'Loan Input Parameters'!$B$16,C9-G9,"0.00") -> 481143.63 | I9: =H9/'Loan Input Parameters'!$B$13 -> 0.95996894 | J9: =J8 -> 0.23 | K9: {=IF( AND(MONTH($B9)=1,SUMPRODUCT(--(MONTH($B$4:B9)=1))=1), K8*(1-22%*J9), IF( AND(MONTH($B9)=1,SUMPRODUCT(--(MONTH($B$4:B9)=1))=2), K8*(1-20%*J9), IF($A9<13,K8*(1-(J9*4%)), IF($A9<25,K8*(1-(J9*5%)),K8*(1-J9/12) ) ) ))} -> 434597.1 | L9: =IF(K9*'Loan Input Parameters'!$B$41<'Loan Input Parameters'!$B$42,'Loan Input Parameters'!$B$42,K9*'Loan Input Parameters'!$B$41) -> 0 | M9: =K9-L9 -> 434597.1 | N9: =H9-(K9-L9) -> 46546.527 | O9: =IF('Loan Input Parameters'!$B$8*3%<=4000,4000,IF('Loan Input Parameters'!$B$8*3%>=18000,18000,'Loan Input Parameters'!$B$8*3%)) -> 15000 | P9: =IF(N9<0,O9,N9+O9) -> 61546.527
A10: =A9+1 -> 7 | B10: =EOMONTH(B9,1) -> 45412 | C10: =IF(ROUND(H9,0)>0,H9,0) -> 481143.63 | D10: =IF(A10<'Loan Input Parameters'!$B$16,'Loan Input Parameters'!$B$24,IF(A10='Loan Input Parameters'!$B$16,'Loan Input Parameters'!$B$24+'Loan Input Parameters'!$B$20,0)) -> 7931.5631 | E10: =IF($A10<'Loan Input Parameters'!$B$16,C10*'Loan Input Parameters'!$B$15/12,"0.00") -> 4410.4833 | F10: =IF(A10<='Loan Input Parameters'!$B$16,'Loan Input Parameters'!$B$23,0) -> 69 | G10: =IF($A10<'Loan Input Parameters'!$B$16,D10-E10-F10,"0.00") -> 3452.0798 | H10: =IF($A10<'Loan Input Parameters'!$B$16,C10-G10,"0.00") -> 477691.55 | I10: =H10/'Loan Input Parameters'!$B$13 -> 0.95308141 | J10: =J9 -> 0.23 | K10: {=IF( AND(MONTH($B10)=1,SUMPRODUCT(--(MONTH($B$4:B10)=1))=1), K9*(1-22%*J10), IF( AND(MONTH($B10)=1,SUMPRODUCT(--(MONTH($B$4:B10)=1))=2), K9*(1-20%*J10), IF($A10<13,K9*(1-(J10*4%)), IF($A10<25,K9*(1-(J10*5%)),K9*(1-J10/12) ) ) ))} -> 430598.81 | L10: =IF(K10*'Loan Input Parameters'!$B$41<'Loan Input Parameters'!$B$42,'Loan Input Parameters'!$B$42,K10*'Loan Input Parameters'!$B$41) -> 0 | M10: =K10-L10 -> 430598.81 | N10: =H10-(K10-L10) -> 47092.741 | O10: =IF('Loan Input Parameters'!$B$8*3%<=4000,4000,IF('Loan Input Parameters'!$B$8*3%>=18000,18000,'Loan Input Parameters'!$B$8*3%)) -> 15000 | P10: =IF(N10<0,O10,N10+O10) -> 62092.741
A11: =A10+1 -> 8 | B11: =EOMONTH(B10,1) -> 45443 | C11: =IF(ROUND(H10,0)>0,H10,0) -> 477691.55 | D11: =IF(A11<'Loan Input Parameters'!$B$16,'Loan Input Parameters'!$B$24,IF(A11='Loan Input Parameters'!$B$16,'Loan Input Parameters'!$B$24+'Loan Input Parameters'!$B$20,0)) -> 7931.5631 | E11: =IF($A11<'Loan Input Parameters'!$B$16,C11*'Loan Input Parameters'!$B$15/12,"0.00") -> 4378.8392 | F11: =IF(A11<='Loan Input Parameters'!$B$16,'Loan Input Parameters'!$B$23,0) -> 69 | G11: =IF($A11<'Loan Input Parameters'!$B$16,D11-E11-F11,"0.00") -> 3483.7238 | H11: =IF($A11<'Loan Input Parameters'!$B$16,C11-G11,"0.00") -> 474207.83 | I11: =H11/'Loan Input Parameters'!$B$13 -> 0.94613075 | J11: =J10 -> 0.23 | K11: {=IF( AND(MONTH($B11)=1,SUMPRODUCT(--(MONTH($B$4:B11)=1))=1), K10*(1-22%*J11), IF( AND(MONTH($B11)=1,SUMPRODUCT(--(MONTH($B$4:B11)=1))=2), K10*(1-20%*J11), IF($A11<13,K10*(1-(J11*4%)), IF($A11<25,K10*(1-(J11*5%)),K10*(1-J11/12) ) ) ))} -> 426637.3 | L11: =IF(K11*'Loan Input Parameters'!$B$41<'Loan Input Parameters'!$B$42,'Loan Input Parameters'!$B$42,K11*'Loan Input Parameters'!$B$41) -> 0 | M11: =K11-L11 -> 426637.3 | N11: =H11-(K11-L11) -> 47570.526 | O11: =IF('Loan Input Parameters'!$B$8*3%<=4000,4000,IF('Loan Input Parameters'!$B$8*3%>=18000,18000,'Loan Input Parameters'!$B$8*3%)) -> 15000 | P11: =IF(N11<0,O11,N11+O11) -> 62570.526
A12: =A11+1 -> 9 | B12: =EOMONTH(B11,1) -> 45473 | C12: =IF(ROUND(H11,0)>0,H11,0) -> 474207.83 | D12: =IF(A12<'Loan Input Parameters'!$B$16,'Loan Input Parameters'!$B$24,IF(A12='Loan Input Parameters'!$B$16,'Loan Input Parameters'!$B$24+'Loan Input Parameters'!$B$20,0)) -> 7931.5631 | E12: =IF($A12<'Loan Input Parameters'!$B$16,C12*'Loan Input Parameters'!$B$15/12,"0.00") -> 4346.9051 | F12: =IF(A12<='Loan Input Parameters'!$B$16,'Loan Input Parameters'!$B$23,0) -> 69 | G12: =IF($A12<'Loan Input Parameters'!$B$16,D12-E12-F12,"0.00") -> 3515.658 | H12: =IF($A12<'Loan Input Parameters'!$B$16,C12-G12,"0.00") -> 470692.17 | I12: =H12/'Loan Input Parameters'!$B$13 -> 0.93911637 | J12: =J11 -> 0.23 | K12: {=IF( AND(MONTH($B12)=1,SUMPRODUCT(--(MONTH($B$4:B12)=1))=1), K11*(1-22%*J12), IF( AND(MONTH($B12)=1,SUMPRODUCT(--(MONTH($B$4:B12)=1))=2), K11*(1-20%*J12), IF($A12<13,K11*(1-(J12*4%)), IF($A12<25,K11*(1-(J12*5%)),K11*(1-J12/12) ) ) ))} -> 422712.24 | L12: =IF(K12*'Loan Input Parameters'!$B$41<'Loan Input Parameters'!$B$42,'Loan Input Parameters'!$B$42,K12*'Loan Input Parameters'!$B$41) -> 0 | M12: =K12-L12 -> 422712.24 | N12: =H12-(K12-L12) -> 47979.931 | O12: =IF('Loan Input Parameters'!$B$8*3%<=4000,4000,IF('Loan Input Parameters'!$B$8*3%>=18000,18000,'Loan Input Parameters'!$B$8*3%)) -> 15000 | P12: =IF(N12<0,O12,N12+O12) -> 62979.931
A13: =A12+1 -> 10 | B13: =EOMONTH(B12,1) -> 45504 | C13: =IF(ROUND(H12,0)>0,H12,0) -> 470692.17 | D13: =IF(A13<'Loan Input Parameters'!$B$16,'Loan Input Parameters'!$B$24,IF(A13='Loan Input Parameters'!$B$16,'Loan Input Parameters'!$B$24+'Loan Input Parameters'!$B$20,0)) -> 7931.5631 | E13: =IF($A13<'Loan Input Parameters'!$B$16,C13*'Loan Input Parameters'!$B$15/12,"0.00") -> 4314.6782 | F13: =IF(A13<='Loan Input Parameters'!$B$16,'Loan Input Parameters'!$B$23,0) -> 69 | G13: =IF($A13<'Loan Input Parameters'!$B$16,D13-E13-F13,"0.00") -> 3547.8848 | H13: =IF($A13<'Loan Input Parameters'!$B$16,C13-G13,"0.00") -> 467144.29 | I13: =H13/'Loan Input Parameters'!$B$13 -> 0.9320377 | J13: =J12 -> 0.23 | K13: {=IF( AND(MONTH($B13)=1,SUMPRODUCT(--(MONTH($B$4:B13)=1))=1), K12*(1-22%*J13), IF( AND(MONTH($B13)=1,SUMPRODUCT(--(MONTH($B$4:B13)=1))=2), K12*(1-20%*J13), IF($A13<13,K12*(1-(J13*4%)), IF($A13<25,K12*(1-(J13*5%)),K12*(1-J13/12) ) ) ))} -> 418823.29 | L13: =IF(K13*'Loan Input Parameters'!$B$41<'Loan Input Parameters'!$B$42,'Loan Input Parameters'!$B$42,K13*'Loan Input Parameters'!$B$41) -> 0 | M13: =K13-L13 -> 418823.29 | N13: =H13-(K13-L13) -> 48320.999 | O13: =IF('Loan Input Parameters'!$B$8*3%<=4000,4000,IF('Loan Input Parameters'!$B$8*3%>=18000,18000,'Loan Input Parameters'!$B$8*3%)) -> 15000 | P13: =IF(N13<0,O13,N13+O13) -> 63320.999
A14: =A13+1 -> 11 | B14: =EOMONTH(B13,1) -> 45535 | C14: =IF(ROUND(H13,0)>0,H13,0) -> 467144.29 | D14: =IF(A14<'Loan Input Parameters'!$B$16,'Loan Input Parameters'!$B$24,IF(A14='Loan Input Parameters'!$B$16,'Loan Input Parameters'!$B$24+'Loan Input Parameters'!$B$20,0)) -> 7931.5631 | E14: =IF($A14<'Loan Input Parameters'!$B$16,C14*'Loan Input Parameters'!$B$15/12,"0.00") -> 4282.1559 | F14: =IF(A14<='Loan Input Parameters'!$B$16,'Loan Input Parameters'!$B$23,0) -> 69 | G14: =IF($A14<'Loan Input Parameters'!$B$16,D14-E14-F14,"0.00") -> 3580.4071 | H14: =IF($A14<'Loan Input Parameters'!$B$16,C14-G14,"0.00") -> 463563.88 | I14: =H14/'Loan Input Parameters'!$B$13 -> 0.92489414 | J14: =J13 -> 0.23 | K14: {=IF( AND(MONTH($B14)=1,SUMPRODUCT(--(MONTH($B$4:B14)=1))=1), K13*(1-22%*J14), IF( AND(MONTH($B14)=1,SUMPRODUCT(--(MONTH($B$4:B14)=1))=2), K13*(1-20%*J14), IF($A14<13,K13*(1-(J14*4%)), IF($A14<25,K13*(1-(J14*5%)),K13*(1-J14/12) ) ) ))} -> 414970.11 | L14: =IF(K14*'Loan Input Parameters'!$B$41<'Loan Input Parameters'!$B$42,'Loan Input Parameters'!$B$42,K14*'Loan Input Parameters'!$B$41) -> 0 | M14: =K14-L14 -> 414970.11 | N14: =H14-(K14-L14) -> 48593.766 | O14: =IF('Loan Input Parameters'!$B$8*3%<=4000,4000,IF('Loan Input Parameters'!$B$8*3%>=18000,18000,'Loan Input Parameters'!$B$8*3%)) -> 15000 | P14: =IF(N14<0,O14,N14+O14) -> 63593.766
A15: =A14+1 -> 12 | B15: =EOMONTH(B14,1) -> 45565 | C15: =IF(ROUND(H14,0)>0,H14,0) -> 463563.88 | D15: =IF(A15<'Loan Input Parameters'!$B$16,'Loan Input Parameters'!$B$24,IF(A15='Loan Input Parameters'!$B$16,'Loan Input Parameters'!$B$24+'Loan Input Parameters'!$B$20,0)) -> 7931.5631 | E15: =IF($A15<'Loan Input Parameters'!$B$16,C15*'Loan Input Parameters'!$B$15/12,"0.00") -> 4249.3356 | F15: =IF(A15<='Loan Input Parameters'!$B$16,'Loan Input Parameters'!$B$23,0) -> 69 | G15: =IF($A15<'Loan Input Parameters'!$B$16,D15-E15-F15,"0.00") -> 3613.2275 | H15: =IF($A15<'Loan Input Parameters'!$B$16,C15-G15,"0.00") -> 459950.65 | I15: =H15/'Loan Input Parameters'!$B$13 -> 0.91768509 | J15: =J14 -> 0.23 | K15: {=IF( AND(MONTH($B15)=1,SUMPRODUCT(--(MONTH($B$4:B15)=1))=1), K14*(1-22%*J15), IF( AND(MONTH($B15)=1,SUMPRODUCT(--(MONTH($B$4:B15)=1))=2), K14*(1-20%*J15), IF($A15<13,K14*(1-(J15*4%)), IF($A15<25,K14*(1-(J15*5%)),K14*(1-J15/12) ) ) ))} -> 411152.39 | L15: =IF(K15*'Loan Input Parameters'!$B$41<'Loan Input Parameters'!$B$42,'Loan Input Parameters'!$B$42,K15*'Loan Input Parameters'!$B$41) -> 0 | M15: =K15-L15 -> 411152.39 | N15: =H15-(K15-L15) -> 48798.264 | O15: =IF('Loan Input Parameters'!$B$8*3%<=4000,4000,IF('Loan Input Parameters'!$B$8*3%>=18000,18000,'Loan Input Parameters'!$B$8*3%)) -> 15000 | P15: =IF(N15<0,O15,N15+O15) -> 63798.264
A16: =A15+1 -> 13 | B16: =EOMONTH(B15,1) -> 45596 | C16: =IF(ROUND(H15,0)>0,H15,0) -> 459950.65 | D16: =IF(A16<'Loan Input Parameters'!$B$16,'Loan Input Parameters'!$B$24,IF(A16='Loan Input Parameters'!$B$16,'Loan Input Parameters'!$B$24+'Loan Input Parameters'!$B$20,0)) -> 7931.5631 | E16: =IF($A16<'Loan Input Parameters'!$B$16,C16*'Loan Input Parameters'!$B$15/12,"0.00") -> 4216.2143 | F16: =IF(A16<='Loan Input Parameters'!$B$16,'Loan Input Parameters'!$B$23,0) -> 69 | G16: =IF($A16<'Loan Input Parameters'!$B$16,D16-E16-F16,"0.00") -> 3646.3488 | H16: =IF($A16<'Loan Input Parameters'!$B$16,C16-G16,"0.00") -> 456304.3 | I16: =H16/'Loan Input Parameters'!$B$13 -> 0.91040996 | J16: =IF('Loan Input Parameters'!$B$32="Overide",'Loan Input Parameters'!$C$35,'Loan Input Parameters'!$B$35) -> 0.15 | K16: =_xlfn.LET(_xlpm.DEPRECIATION,IF('Loan Input Parameters'!$B$6="Used",0.08,0.05), IF( MONTH($B16)=1, K15*(1-(35%*J16)+_xlpm.DEPRECIATION),K15*(1-_xlpm.DEPRECIATION))) -> 390594.77 | L16: =IF(K16*'Loan Input Parameters'!$B$41<'Loan Input Parameters'!$B$42,'Loan Input Parameters'!$B$42,K16*'Loan Input Parameters'!$B$41) -> 0 | M16: =K16-L16 -> 390594.77 | N16: =H16-(K16-L16) -> 65709.534 | O16: =IF('Loan Input Parameters'!$B$8*3%<=4000,4000,IF('Loan Input Parameters'!$B$8*3%>=18000,18000,'Loan Input Parameters'!$B$8*3%)) -> 15000 | P16: =IF(N16<0,O16,N16+O16) -> 80709.534
A17: =A16+1 -> 14 | B17: =EOMONTH(B16,1) -> 45626 | C17: =IF(ROUND(H16,0)>0,H16,0) -> 456304.3 | D17: =IF(A17<'Loan Input Parameters'!$B$16,'Loan Input Parameters'!$B$24,IF(A17='Loan Input Parameters'!$B$16,'Loan Input Parameters'!$B$24+'Loan Input Parameters'!$B$20,0)) -> 7931.5631 | E17: =IF($A17<'Loan Input Parameters'!$B$16,C17*'Loan Input Parameters'!$B$15/12,"0.00") -> 4182.7894 | F17: =IF(A17<='Loan Input Parameters'!$B$16,'Loan Input Parameters'!$B$23,0) -> 69 | G17: =IF($A17<'Loan Input Parameters'!$B$16,D17-E17-F17,"0.00") -> 3679.7736 | H17: =IF($A17<'Loan Input Parameters'!$B$16,C17-G17,"0.00") -> 452624.53 | I17: =H17/'Loan Input Parameters'!$B$13 -> 0.90306815 | J17: =IF('Loan Input Parameters'!$B$32="Overide",'Loan Input Parameters'!$C$35,'Loan Input Parameters'!$B$35) -> 0.15 | K17: {=IF( AND(MONTH($B17)=1,SUMPRODUCT(--(MONTH($B$4:B17)=1))=1), K16*(1-22%*J17), IF( AND(MONTH($B17)=1,SUMPRODUCT(--(MONTH($B$4:B17)=1))=2), K16*(1-20%*J17), IF($A17<13,K16*(1-(J17*4%)), IF($A17<25,K16*(1-(J17*5%)),K16*(1-J17/12)))))} -> 387665.31 | L17: =IF(K17*'Loan Input Parameters'!$B$41<'Loan Input Parameters'!$B$42,'Loan Input Parameters'!$B$42,K17*'Loan Input Parameters'!$B$41) -> 0 | M17: =K17-L17 -> 387665.31 | N17: =H17-(K17-L17) -> 64959.221 | O17: =IF('Loan Input Parameters'!$B$8*3%<=4000,4000,IF('Loan Input Parameters'!$B$8*3%>=18000,18000,'Loan Input Parameters'!$B$8*3%)) -> 15000 | P17: =IF(N17<0,O17,N17+O17) -> 79959.221
A18: =A17+1 -> 15 | B18: =EOMONTH(B17,1) -> 45657 | C18: =IF(ROUND(H17,0)>0,H17,0) -> 452624.53 | D18: =IF(A18<'Loan Input Parameters'!$B$16,'Loan Input Parameters'!$B$24,IF(A18='Loan Input Parameters'!$B$16,'Loan Input Parameters'!$B$24+'Loan Input Parameters'!$B$20,0)) -> 7931.5631 | E18: =IF($A18<'Loan Input Parameters'!$B$16,C18*'Loan Input Parameters'!$B$15/12,"0.00") -> 4149.0582 | F18: =IF(A18<='Loan Input Parameters'!$B$16,'Loan Input Parameters'!$B$23,0) -> 69 | G18: =IF($A18<'Loan Input Parameters'!$B$16,D18-E18-F18,"0.00") -> 3713.5049 | H18: =IF($A18<'Loan Input Parameters'!$B$16,C18-G18,"0.00") -> 448911.02 | I18: =H18/'Loan Input Parameters'!$B$13 -> 0.89565903 | J18: =IF('Loan Input Parameters'!$B$32="Overide",'Loan Input Parameters'!$C$35,'Loan Input Parameters'!$B$35) -> 0.15 | K18: {=IF( AND(MONTH($B18)=1,SUMPRODUCT(--(MONTH($B$4:B18)=1))=1), K17*(1-22%*J18), IF( AND(MONTH($B18)=1,SUMPRODUCT(--(MONTH($B$4:B18)=1))=2), K17*(1-20%*J18), IF($A18<13,K17*(1-(J18*4%)), IF($A18<25,K17*(1-(J18*5%)),K17*(1-J18/12) ) ) ))} -> 384757.82 | L18: =IF(K18*'Loan Input Parameters'!$B$41<'Loan Input Parameters'!$B$42,'Loan Input Parameters'!$B$42,K18*'Loan Input Parameters'!$B$41) -> 0 | M18: =K18-L18 -> 384757.82 | N18: =H18-(K18-L18) -> 64153.206 | O18: =IF('Loan Input Parameters'!$B$8*3%<=4000,4000,IF('Loan Input Parameters'!$B$8*3%>=18000,18000,'Loan Input Parameters'!$B$8*3%)) -> 15000 | P18: =IF(N18<0,O18,N18+O18) -> 79153.206
A19: =A18+1 -> 16 | B19: =EOMONTH(B18,1) -> 45688 | C19: =IF(ROUND(H18,0)>0,H18,0) -> 448911.02 | D19: =IF(A19<'Loan Input Parameters'!$B$16,'Loan Input Parameters'!$B$24,IF(A19='Loan Input Parameters'!$B$16,'Loan Input Parameters'!$B$24+'Loan Input Parameters'!$B$20,0)) -> 7931.5631 | E19: =IF($A19<'Loan Input Parameters'!$B$16,C19*'Loan Input Parameters'!$B$15/12,"0.00") -> 4115.0177 | F19: =IF(A19<='Loan Input Parameters'!$B$16,'Loan Input Parameters'!$B$23,0) -> 69 | G19: =IF($A19<'Loan Input Parameters'!$B$16,D19-E19-F19,"0.00") -> 3747.5453 | H19: =IF($A19<'Loan Input Parameters'!$B$16,C19-G19,"0.00") -> 445163.48 | I19: =H19/'Loan Input Parameters'!$B$13 -> 0.888182 | J19: =IF('Loan Input Parameters'!$B$32="Overide",'Loan Input Parameters'!$C$35,'Loan Input Parameters'!$B$35) -> 0.15 | K19: {=IF( AND(MONTH($B19)=1,SUMPRODUCT(--(MONTH($B$4:B19)=1))=1), K18*(1-22%*J19), IF( AND(MONTH($B19)=1,SUMPRODUCT(--(MONTH($B$4:B19)=1))=2), K18*(1-20%*J19), IF($A19<13,K18*(1-(J19*4%)), IF($A19<25,K18*(1-(J19*5%)),K18*(1-J19/12) ) ) ))} -> 373215.08 | L19: =IF(K19*'Loan Input Parameters'!$B$41<'Loan Input Parameters'!$B$42,'Loan Input Parameters'!$B$42,K19*'Loan Input Parameters'!$B$41) -> 0 | M19: =K19-L19 -> 373215.08 | N19: =H19-(K19-L19) -> 71948.396 | O19: =IF('Loan Input Parameters'!$B$8*3%<=4000,4000,IF('Loan Input Parameters'!$B$8*3%>=18000,18000,'Loan Input Parameters'!$B$8*3%)) -> 15000 | P19: =IF(N19<0,O19,N19+O19) -> 86948.396
A20: =A19+1 -> 17 | B20: =EOMONTH(B19,1) -> 45716 | C20: =IF(ROUND(H19,0)>0,H19,0) -> 445163.48 | D20: =IF(A20<'Loan Input Parameters'!$B$16,'Loan Input Parameters'!$B$24,IF(A20='Loan Input Parameters'!$B$16,'Loan Input Parameters'!$B$24+'Loan Input Parameters'!$B$20,0)) -> 7931.5631 | E20: =IF($A20<'Loan Input Parameters'!$B$16,C20*'Loan Input Parameters'!$B$15/12,"0.00") -> 4080.6652 | F20: =IF(A20<='Loan Input Parameters'!$B$16,'Loan Input Parameters'!$B$23,0) -> 69 | G20: =IF($A20<'Loan Input Parameters'!$B$16,D20-E20-F20,"0.00") -> 3781.8978 | H20: =IF($A20<'Loan Input Parameters'!$B$16,C20-G20,"0.00") -> 441381.58 | I20: =H20/'Loan Input Parameters'!$B$13 -> 0.88063642 | J20: =IF('Loan Input Parameters'!$B$32="Overide",'Loan Input Parameters'!$C$35,'Loan Input Parameters'!$B$35) -> 0.15 | K20: {=IF( AND(MONTH($B20)=1,SUMPRODUCT(--(MONTH($B$4:B20)=1))=1), K19*(1-22%*J20), IF( AND(MONTH($B20)=1,SUMPRODUCT(--(MONTH($B$4:B20)=1))=2), K19*(1-20%*J20), IF($A20<13,K19*(1-(J20*4%)), IF($A20<25,K19*(1-(J20*5%)),K19*(1-J20/12) ) ) ))} -> 370415.97 | L20: =IF(K20*'Loan Input Parameters'!$B$41<'Loan Input Parameters'!$B$42,'Loan Input Parameters'!$B$42,K20*'Loan Input Parameters'!$B$41) -> 0 | M20: =K20-L20 -> 370415.97 | N20: =H20-(K20-L20) -> 70965.611 | O20: =IF('Loan Input Parameters'!$B$8*3%<=4000,4000,IF('Loan Input Parameters'!$B$8*3%>=18000,18000,'Loan Input Parameters'!$B$8*3%)) -> 15000 | P20: =IF(N20<0,O20,N20+O20) -> 85965.611
A21: =A20+1 -> 18 | B21: =EOMONTH(B20,1) -> 45747 | C21: =IF(ROUND(H20,0)>0,H20,0) -> 441381.58 | D21: =IF(A21<'Loan Input Parameters'!$B$16,'Loan Input Parameters'!$B$24,IF(A21='Loan Input Parameters'!$B$16,'Loan Input Parameters'!$B$24+'Loan Input Parameters'!$B$20,0)) -> 7931.5631 | E21: =IF($A21<'Loan Input Parameters'!$B$16,C21*'Loan Input Parameters'!$B$15/12,"0.00") -> 4045.9978 | F21: =IF(A21<='Loan Input Parameters'!$B$16,'Loan Input Parameters'!$B$23,0) -> 69 | G21: =IF($A21<'Loan Input Parameters'!$B$16,D21-E21-F21,"0.00") -> 3816.5652 | H21: =IF($A21<'Loan Input Parameters'!$B$16,C21-G21,"0.00") -> 437565.02 | I21: =H21/'Loan Input Parameters'!$B$13 -> 0.87302168 | J21: =IF('Loan Input Parameters'!$B$32="Overide",'Loan Input Parameters'!$C$35,'Loan Input Parameters'!$B$35) -> 0.15 | K21: {=IF( AND(MONTH($B21)=1,SUMPRODUCT(--(MONTH($B$4:B21)=1))=1), K20*(1-22%*J21), IF( AND(MONTH($B21)=1,SUMPRODUCT(--(MONTH($B$4:B21)=1))=2), K20*(1-20%*J21), IF($A21<13,K20*(1-(J21*4%)), IF($A21<25,K20*(1-(J21*5%)),K20*(1-J21/12) ) ) ))} -> 367637.85 | L21: =IF(K21*'Loan Input Parameters'!$B$41<'Loan Input Parameters'!$B$42,'Loan Input Parameters'!$B$42,K21*'Loan Input Parameters'!$B$41) -> 0 | M21: =K21-L21 -> 367637.85 | N21: =H21-(K21-L21) -> 69927.165 | O21: =IF('Loan Input Parameters'!$B$8*3%<=4000,4000,IF('Loan Input Parameters'!$B$8*3%>=18000,18000,'Loan Input Parameters'!$B$8*3%)) -> 15000 | P21: =IF(N21<0,O21,N21+O21) -> 84927.165
A22: =A21+1 -> 19 | B22: =EOMONTH(B21,1) -> 45777 | C22: =IF(ROUND(H21,0)>0,H21,0) -> 437565.02 | D22: =IF(A22<'Loan Input Parameters'!$B$16,'Loan Input Parameters'!$B$24,IF(A22='Loan Input Parameters'!$B$16,'Loan Input Parameters'!$B$24+'Loan Input Parameters'!$B$20,0)) -> 7931.5631 | E22: =IF($A22<'Loan Input Parameters'!$B$16,C22*'Loan Input Parameters'!$B$15/12,"0.00") -> 4011.0126 | F22: =IF(A22<='Loan Input Parameters'!$B$16,'Loan Input Parameters'!$B$23,0) -> 69 | G22: =IF($A22<'Loan Input Parameters'!$B$16,D22-E22-F22,"0.00") -> 3851.5504 | H22: =IF($A22<'Loan Input Parameters'!$B$16,C22-G22,"0.00") -> 433713.46 | I22: =H22/'Loan Input Parameters'!$B$13 -> 0.86533714 | J22: =IF('Loan Input Parameters'!$B$32="Overide",'Loan Input Parameters'!$C$35,'Loan Input Parameters'!$B$35) -> 0.15 | K22: {=IF( AND(MONTH($B22)=1,SUMPRODUCT(--(MONTH($B$4:B22)=1))=1), K21*(1-22%*J22), IF( AND(MONTH($B22)=1,SUMPRODUCT(--(MONTH($B$4:B22)=1))=2), K21*(1-20%*J22), IF($A22<13,K21*(1-(J22*4%)), IF($A22<25,K21*(1-(J22*5%)),K21*(1-J22/12) ) ) ))} -> 364880.57 | L22: =IF(K22*'Loan Input Parameters'!$B$41<'Loan Input Parameters'!$B$42,'Loan Input Parameters'!$B$42,K22*'Loan Input Parameters'!$B$41) -> 0 | M22: =K22-L22 -> 364880.57 | N22: =H22-(K22-L22) -> 68832.899 | O22: =IF('Loan Input Parameters'!$B$8*3%<=4000,4000,IF('Loan Input Parameters'!$B$8*3%>=18000,18000,'Loan Input Parameters'!$B$8*3%)) -> 15000 | P22: =IF(N22<0,O22,N22+O22) -> 83832.899
A23: =A22+1 -> 20 | B23: =EOMONTH(B22,1) -> 45808 | C23: =IF(ROUND(H22,0)>0,H22,0) -> 433713.46 | D23: =IF(A23<'Loan Input Parameters'!$B$16,'Loan Input Parameters'!$B$24,IF(A23='Loan Input Parameters'!$B$16,'Loan Input Parameters'!$B$24+'Loan Input Parameters'!$B$20,0)) -> 7931.5631 | E23: =IF($A23<'Loan Input Parameters'!$B$16,C23*'Loan Input Parameters'!$B$15/12,"0.00") -> 3975.7068 | F23: =IF(A23<='Loan Input Parameters'!$B$16,'Loan Input Parameters'!$B$23,0) -> 69 | G23: =IF($A23<'Loan Input Parameters'!$B$16,D23-E23-F23,"0.00") -> 3886.8563 | H23: =IF($A23<'Loan Input Parameters'!$B$16,C23-G23,"0.00") -> 429826.61 | I23: =H23/'Loan Input Parameters'!$B$13 -> 0.85758216 | J23: =IF('Loan Input Parameters'!$B$32="Overide",'Loan Input Parameters'!$C$35,'Loan Input Parameters'!$B$35) -> 0.15 | K23: {=IF( AND(MONTH($B23)=1,SUMPRODUCT(--(MONTH($B$4:B23)=1))=1), K22*(1-22%*J23), IF( AND(MONTH($B23)=1,SUMPRODUCT(--(MONTH($B$4:B23)=1))=2), K22*(1-20%*J23), IF($A23<13,K22*(1-(J23*4%)), IF($A23<25,K22*(1-(J23*5%)),K22*(1-J23/12) ) ) ))} -> 362143.96 | L23: =IF(K23*'Loan Input Parameters'!$B$41<'Loan Input Parameters'!$B$42,'Loan Input Parameters'!$B$42,K23*'Loan Input Parameters'!$B$41) -> 0 | M23: =K23-L23 -> 362143.96 | N23: =H23-(K23-L23) -> 67682.647 | O23: =IF('Loan Input Parameters'!$B$8*3%<=4000,4000,IF('Loan Input Parameters'!$B$8*3%>=18000,18000,'Loan Input Parameters'!$B$8*3%)) -> 15000 | P23: =IF(N23<0,O23,N23+O23) -> 82682.647
A24: =A23+1 -> 21 | B24: =EOMONTH(B23,1) -> 45838 | C24: =IF(ROUND(H23,0)>0,H23,0) -> 429826.61 | D24: =IF(A24<'Loan Input Parameters'!$B$16,'Loan Input Parameters'!$B$24,IF(A24='Loan Input Parameters'!$B$16,'Loan Input Parameters'!$B$24+'Loan Input Parameters'!$B$20,0)) -> 7931.5631 | E24: =IF($A24<'Loan Input Parameters'!$B$16,C24*'Loan Input Parameters'!$B$15/12,"0.00") -> 3940.0772 | F24: =IF(A24<='Loan Input Parameters'!$B$16,'Loan Input Parameters'!$B$23,0) -> 69 | G24: =IF($A24<'Loan Input Parameters'!$B$16,D24-E24-F24,"0.00") -> 3922.4858 | H24: =IF($A24<'Loan Input Parameters'!$B$16,C24-G24,"0.00") -> 425904.12 | I24: =H24/'Loan Input Parameters'!$B$13 -> 0.84975608 | J24: =IF('Loan Input Parameters'!$B$32="Overide",'Loan Input Parameters'!$C$35,'Loan Input Parameters'!$B$35) -> 0.15 | K24: {=IF( AND(MONTH($B24)=1,SUMPRODUCT(--(MONTH($B$4:B24)=1))=1), K23*(1-22%*J24), IF( AND(MONTH($B24)=1,SUMPRODUCT(--(MONTH($B$4:B24)=1))=2), K23*(1-20%*J24), IF($A24<13,K23*(1-(J24*4%)), IF($A24<25,K23*(1-(J24*5%)),K23*(1-J24/12) ) ) ))} -> 359427.88 | L24: =IF(K24*'Loan Input Parameters'!$B$41<'Loan Input Parameters'!$B$42,'Loan Input Parameters'!$B$42,K24*'Loan Input Parameters'!$B$41) -> 0 | M24: =K24-L24 -> 359427.88 | N24: =H24-(K24-L24) -> 66476.241 | O24: =IF('Loan Input Parameters'!$B$8*3%<=4000,4000,IF('Loan Input Parameters'!$B$8*3%>=18000,18000,'Loan Input Parameters'!$B$8*3%)) -> 15000 | P24: =IF(N24<0,O24,N24+O24) -> 81476.241
A25: =A24+1 -> 22 | B25: =EOMONTH(B24,1) -> 45869 | C25: =IF(ROUND(H24,0)>0,H24,0) -> 425904.12 | D25: =IF(A25<'Loan Input Parameters'!$B$16,'Loan Input Parameters'!$B$24,IF(A25='Loan Input Parameters'!$B$16,'Loan Input Parameters'!$B$24+'Loan Input Parameters'!$B$20,0)) -> 7931.5631 | E25: =IF($A25<'Loan Input Parameters'!$B$16,C25*'Loan Input Parameters'!$B$15/12,"0.00") -> 3904.1211 | F25: =IF(A25<='Loan Input Parameters'!$B$16,'Loan Input Parameters'!$B$23,0) -> 69 | G25: =IF($A25<'Loan Input Parameters'!$B$16,D25-E25-F25,"0.00") -> 3958.4419 | H25: =IF($A25<'Loan Input Parameters'!$B$16,C25-G25,"0.00") -> 421945.68 | I25: =H25/'Loan Input Parameters'!$B$13 -> 0.84185827 | J25: =IF('Loan Input Parameters'!$B$32="Overide",'Loan Input Parameters'!$C$35,'Loan Input Parameters'!$B$35) -> 0.15 | K25: {=IF( AND(MONTH($B25)=1,SUMPRODUCT(--(MONTH($B$4:B25)=1))=1), K24*(1-22%*J25), IF( AND(MONTH($B25)=1,SUMPRODUCT(--(MONTH($B$4:B25)=1))=2), K24*(1-20%*J25), IF($A25<13,K24*(1-(J25*4%)), IF($A25<25,K24*(1-(J25*5%)),K24*(1-J25/12) ) ) ))} -> 356732.17 | L25: =IF(K25*'Loan Input Parameters'!$B$41<'Loan Input Parameters'!$B$42,'Loan Input Parameters'!$B$42,K25*'Loan Input Parameters'!$B$41) -> 0 | M25: =K25-L25 -> 356732.17 | N25: =H25-(K25-L25) -> 65213.508 | O25: =IF('Loan Input Parameters'!$B$8*3%<=4000,4000,IF('Loan Input Parameters'!$B$8*3%>=18000,18000,'Loan Input Parameters'!$B$8*3%)) -> 15000 | P25: =IF(N25<0,O25,N25+O25) -> 80213.508
A26: =A25+1 -> 23 | B26: =EOMONTH(B25,1) -> 45900 | C26: =IF(ROUND(H25,0)>0,H25,0) -> 421945.68 | D26: =IF(A26<'Loan Input Parameters'!$B$16,'Loan Input Parameters'!$B$24,IF(A26='Loan Input Parameters'!$B$16,'Loan Input Parameters'!$B$24+'Loan Input Parameters'!$B$20,0)) -> 7931.5631 | E26: =IF($A26<'Loan Input Parameters'!$B$16,C26*'Loan Input Parameters'!$B$15/12,"0.00") -> 3867.8354 | F26: =IF(A26<='Loan Input Parameters'!$B$16,'Loan Input Parameters'!$B$23,0) -> 69 | G26: =IF($A26<'Loan Input Parameters'!$B$16,D26-E26-F26,"0.00") -> 3994.7276 | H26: =IF($A26<'Loan Input Parameters'!$B$16,C26-G26,"0.00") -> 417950.95 | I26: =H26/'Loan Input Parameters'!$B$13 -> 0.83388807 | J26: =IF('Loan Input Parameters'!$B$32="Overide",'Loan Input Parameters'!$C$35,'Loan Input Parameters'!$B$35) -> 0.15 | K26: {=IF( AND(MONTH($B26)=1,SUMPRODUCT(--(MONTH($B$4:B26)=1))=1), K25*(1-22%*J26), IF( AND(MONTH($B26)=1,SUMPRODUCT(--(MONTH($B$4:B26)=1))=2), K25*(1-20%*J26), IF($A26<13,K25*(1-(J26*4%)), IF($A26<25,K25*(1-(J26*5%)),K25*(1-J26/12) ) ) ))} -> 354056.68 | L26: =IF(K26*'Loan Input Parameters'!$B$41<'Loan Input Parameters'!$B$42,'Loan Input Parameters'!$B$42,K26*'Loan Input Parameters'!$B$41) -> 0 | M26: =K26-L26 -> 354056.68 | N26: =H26-(K26-L26) -> 63894.271 | O26: =IF('Loan Input Parameters'!$B$8*3%<=4000,4000,IF('Loan Input Parameters'!$B$8*3%>=18000,18000,'Loan Input Parameters'!$B$8*3%)) -> 15000 | P26: =IF(N26<0,O26,N26+O26) -> 78894.271
A27: =A26+1 -> 24 | B27: =EOMONTH(B26,1) -> 45930 | C27: =IF(ROUND(H26,0)>0,H26,0) -> 417950.95 | D27: =IF(A27<'Loan Input Parameters'!$B$16,'Loan Input Parameters'!$B$24,IF(A27='Loan Input Parameters'!$B$16,'Loan Input Parameters'!$B$24+'Loan Input Parameters'!$B$20,0)) -> 7931.5631 | E27: =IF($A27<'Loan Input Parameters'!$B$16,C27*'Loan Input Parameters'!$B$15/12,"0.00") -> 3831.2171 | F27: =IF(A27<='Loan Input Parameters'!$B$16,'Loan Input Parameters'!$B$23,0) -> 69 | G27: =IF($A27<'Loan Input Parameters'!$B$16,D27-E27-F27,"0.00") -> 4031.346 | H27: =IF($A27<'Loan Input Parameters'!$B$16,C27-G27,"0.00") -> 413919.61 | I27: =H27/'Loan Input Parameters'!$B$13 -> 0.8258448 | J27: =IF('Loan Input Parameters'!$B$32="Overide",'Loan Input Parameters'!$C$35,'Loan Input Parameters'!$B$35) -> 0.15 | K27: {=IF( AND(MONTH($B27)=1,SUMPRODUCT(--(MONTH($B$4:B27)=1))=1), K26*(1-22%*J27), IF( AND(MONTH($B27)=1,SUMPRODUCT(--(MONTH($B$4:B27)=1))=2), K26*(1-20%*J27), IF($A27<13,K26*(1-(J27*4%)), IF($A27<25,K26*(1-(J27*5%)),K26*(1-J27/12) ) ) ))} -> 351401.26 | L27: =IF(K27*'Loan Input Parameters'!$B$41<'Loan Input Parameters'!$B$42,'Loan Input Parameters'!$B$42,K27*'Loan Input Parameters'!$B$41) -> 0 | M27: =K27-L27 -> 351401.26 | N27: =H27-(K27-L27) -> 62518.351 | O27: =IF('Loan Input Parameters'!$B$8*3%<=4000,4000,IF('Loan Input Parameters'!$B$8*3%>=18000,18000,'Loan Input Parameters'!$B$8*3%)) -> 15000 | P27: =IF(N27<0,O27,N27+O27) -> 77518.351
A28: =A27+1 -> 25 | B28: =EOMONTH(B27,1) -> 45961 | C28: =IF(ROUND(H27,0)>0,H27,0) -> 413919.61 | D28: =IF(A28<'Loan Input Parameters'!$B$16,'Loan Input Parameters'!$B$24,IF(A28='Loan Input Parameters'!$B$16,'Loan Input Parameters'!$B$24+'Loan Input Parameters'!$B$20,0)) -> 7931.5631 | E28: =IF($A28<'Loan Input Parameters'!$B$16,C28*'Loan Input Parameters'!$B$15/12,"0.00") -> 3794.2631 | F28: =IF(A28<='Loan Input Parameters'!$B$16,'Loan Input Parameters'!$B$23,0) -> 69 | G28: =IF($A28<'Loan Input Parameters'!$B$16,D28-E28-F28,"0.00") -> 4068.3 | H28: =IF($A28<'Loan Input Parameters'!$B$16,C28-G28,"0.00") -> 409851.31 | I28: =H28/'Loan Input Parameters'!$B$13 -> 0.8177278 | J28: =IF('Loan Input Parameters'!$B$32="Overide",'Loan Input Parameters'!$C$36,'Loan Input Parameters'!$B$36) -> 0.11 | K28: {=IF( AND(MONTH($B28)=1,SUMPRODUCT(--(MONTH($B$4:B28)=1))=1), K27*(1-22%*J28), IF( AND(MONTH($B28)=1,SUMPRODUCT(--(MONTH($B$4:B28)=1))=2), K27*(1-20%*J28), IF($A28<13,K27*(1-(J28*4%)), IF($A28<25,K27*(1-(J28*5%)),K27*(1-J28/12) ) ) ))} -> 348180.08 | L28: =IF(K28*'Loan Input Parameters'!$B$41<'Loan Input Parameters'!$B$42,'Loan Input Parameters'!$B$42,K28*'Loan Input Parameters'!$B$41) -> 0 | M28: =K28-L28 -> 348180.08 | N28: =H28-(K28-L28) -> 61671.229 | O28: =IF('Loan Input Parameters'!$B$8*3%<=4000,4000,IF('Loan Input Parameters'!$B$8*3%>=18000,18000,'Loan Input Parameters'!$B$8*3%)) -> 15000 | P28: =IF(N28<0,O28,N28+O28) -> 76671.229
A29: =A28+1 -> 26 | B29: =EOMONTH(B28,1) -> 45991 | C29: =IF(ROUND(H28,0)>0,H28,0) -> 409851.31 | D29: =IF(A29<'Loan Input Parameters'!$B$16,'Loan Input Parameters'!$B$24,IF(A29='Loan Input Parameters'!$B$16,'Loan Input Parameters'!$B$24+'Loan Input Parameters'!$B$20,0)) -> 7931.5631 | E29: =IF($A29<'Loan Input Parameters'!$B$16,C29*'Loan Input Parameters'!$B$15/12,"0.00") -> 3756.9703 | F29: =IF(A29<='Loan Input Parameters'!$B$16,'Loan Input Parameters'!$B$23,0) -> 69 | G29: =IF($A29<'Loan Input Parameters'!$B$16,D29-E29-F29,"0.00") -> 4105.5927 | H29: =IF($A29<'Loan Input Parameters'!$B$16,C29-G29,"0.00") -> 405745.71 | I29: =H29/'Loan Input Parameters'!$B$13 -> 0.8095364 | J29: =J28 -> 0.11 | K29: {=IF( AND(MONTH($B29)=1,SUMPRODUCT(--(MONTH($B$4:B29)=1))=1), K28*(1-22%*J29), IF( AND(MONTH($B29)=1,SUMPRODUCT(--(MONTH($B$4:B29)=1))=2), K28*(1-20%*J29), IF($A29<13,K28*(1-(J29*4%)), IF($A29<25,K28*(1-(J29*5%)),K28*(1-J29/12) ) ) ))} -> 344988.43 | L29: =IF(K29*'Loan Input Parameters'!$B$41<'Loan Input Parameters'!$B$42,'Loan Input Parameters'!$B$42,K29*'Loan Input Parameters'!$B$41) -> 0 | M29: =K29-L29 -> 344988.43 | N29: =H29-(K29-L29) -> 60757.287 | O29: =IF('Loan Input Parameters'!$B$8*3%<=4000,4000,IF('Loan Input Parameters'!$B$8*3%>=18000,18000,'Loan Input Parameters'!$B$8*3%)) -> 15000 | P29: =IF(N29<0,O29,N29+O29) -> 75757.287
A30: =A29+1 -> 27 | B30: =EOMONTH(B29,1) -> 46022 | C30: =IF(ROUND(H29,0)>0,H29,0) -> 405745.71 | D30: =IF(A30<'Loan Input Parameters'!$B$16,'Loan Input Parameters'!$B$24,IF(A30='Loan Input Parameters'!$B$16,'Loan Input Parameters'!$B$24+'Loan Input Parameters'!$B$20,0)) -> 7931.5631 | E30: =IF($A30<'Loan Input Parameters'!$B$16,C30*'Loan Input Parameters'!$B$15/12,"0.00") -> 3719.3357 | F30: =IF(A30<='Loan Input Parameters'!$B$16,'Loan Input Parameters'!$B$23,0) -> 69 | G30: =IF($A30<'Loan Input Parameters'!$B$16,D30-E30-F30,"0.00") -> 4143.2273 | H30: =IF($A30<'Loan Input Parameters'!$B$16,C30-G30,"0.00") -> 401602.49 | I30: =H30/'Loan Input Parameters'!$B$13 -> 0.80126991 | J30: =J29 -> 0.11 | K30: {=IF( AND(MONTH($B30)=1,SUMPRODUCT(--(MONTH($B$4:B30)=1))=1), K29*(1-22%*J30), IF( AND(MONTH($B30)=1,SUMPRODUCT(--(MONTH($B$4:B30)=1))=2), K29*(1-20%*J30), IF($A30<13,K29*(1-(J30*4%)), IF($A30<25,K29*(1-(J30*5%)),K29*(1-J30/12) ) ) ))} -> 341826.03 | L30: =IF(K30*'Loan Input Parameters'!$B$41<'Loan Input Parameters'!$B$42,'Loan Input Parameters'!$B$42,K30*'Loan Input Parameters'!$B$41) -> 0 | M30: =K30-L30 -> 341826.03 | N30: =H30-(K30-L30) -> 59776.453 | O30: =IF('Loan Input Parameters'!$B$8*3%<=4000,4000,IF('Loan Input Parameters'!$B$8*3%>=18000,18000,'Loan Input Parameters'!$B$8*3%)) -> 15000 | P30: =IF(N30<0,O30,N30+O30) -> 74776.453
A31: =A30+1 -> 28 | B31: =EOMONTH(B30,1) -> 46053 | C31: =IF(ROUND(H30,0)>0,H30,0) -> 401602.49 | D31: =IF(A31<'Loan Input Parameters'!$B$16,'Loan Input Parameters'!$B$24,IF(A31='Loan Input Parameters'!$B$16,'Loan Input Parameters'!$B$24+'Loan Input Parameters'!$B$20,0)) -> 7931.5631 | E31: =IF($A31<'Loan Input Parameters'!$B$16,C31*'Loan Input Parameters'!$B$15/12,"0.00") -> 3681.3561 | F31: =IF(A31<='Loan Input Parameters'!$B$16,'Loan Input Parameters'!$B$23,0) -> 69 | G31: =IF($A31<'Loan Input Parameters'!$B$16,D31-E31-F31,"0.00") -> 4181.2069 | H31: =IF($A31<'Loan Input Parameters'!$B$16,C31-G31,"0.00") -> 397421.28 | I31: =H31/'Loan Input Parameters'!$B$13 -> 0.79292764 | J31: =J30 -> 0.11 | K31: {=IF( AND(MONTH($B31)=1,SUMPRODUCT(--(MONTH($B$4:B31)=1))=1), K30*(1-22%*J31), IF( AND(MONTH($B31)=1,SUMPRODUCT(--(MONTH($B$4:B31)=1))=2), K30*(1-20%*J31), IF($A31<13,K30*(1-(J31*4%)), IF($A31<25,K30*(1-(J31*5%)),K30*(1-J31/12) ) ) ))} -> 338692.63 | L31: =IF(K31*'Loan Input Parameters'!$B$41<'Loan Input Parameters'!$B$42,'Loan Input Parameters'!$B$42,K31*'Loan Input Parameters'!$B$41) -> 0 | M31: =K31-L31 -> 338692.63 | N31: =H31-(K31-L31) -> 58728.652 | O31: =IF('Loan Input Parameters'!$B$8*3%<=4000,4000,IF('Loan Input Parameters'!$B$8*3%>=18000,18000,'Loan Input Parameters'!$B$8*3%)) -> 15000 | P31: =IF(N31<0,O31,N31+O31) -> 73728.652
A32: =A31+1 -> 29 | B32: =EOMONTH(B31,1) -> 46081 | C32: =IF(ROUND(H31,0)>0,H31,0) -> 397421.28 | D32: =IF(A32<'Loan Input Parameters'!$B$16,'Loan Input Parameters'!$B$24,IF(A32='Loan Input Parameters'!$B$16,'Loan Input Parameters'!$B$24+'Loan Input Parameters'!$B$20,0)) -> 7931.5631 | E32: =IF($A32<'Loan Input Parameters'!$B$16,C32*'Loan Input Parameters'!$B$15/12,"0.00") -> 3643.0284 | F32: =IF(A32<='Loan Input Parameters'!$B$16,'Loan Input Parameters'!$B$23,0) -> 69 | G32: =IF($A32<'Loan Input Parameters'!$B$16,D32-E32-F32,"0.00") -> 4219.5347 | H32: =IF($A32<'Loan Input Parameters'!$B$16,C32-G32,"0.00") -> 393201.75 | I32: =H32/'Loan Input Parameters'!$B$13 -> 0.7845089 | J32: =J31 -> 0.11 | K32: {=IF( AND(MONTH($B32)=1,SUMPRODUCT(--(MONTH($B$4:B32)=1))=1), K31*(1-22%*J32), IF( AND(MONTH($B32)=1,SUMPRODUCT(--(MONTH($B$4:B32)=1))=2), K31*(1-20%*J32), IF($A32<13,K31*(1-(J32*4%)), IF($A32<25,K31*(1-(J32*5%)),K31*(1-J32/12) ) ) ))} -> 335587.95 | L32: =IF(K32*'Loan Input Parameters'!$B$41<'Loan Input Parameters'!$B$42,'Loan Input Parameters'!$B$42,K32*'Loan Input Parameters'!$B$41) -> 0 | M32: =K32-L32 -> 335587.95 | N32: =H32-(K32-L32) -> 57613.8 | O32: =IF('Loan Input Parameters'!$B$8*3%<=4000,4000,IF('Loan Input Parameters'!$B$8*3%>=18000,18000,'Loan Input Parameters'!$B$8*3%)) -> 15000 | P32: =IF(N32<0,O32,N32+O32) -> 72613.8
A33: =A32+1 -> 30 | B33: =EOMONTH(B32,1) -> 46112 | C33: =IF(ROUND(H32,0)>0,H32,0) -> 393201.75 | D33: =IF(A33<'Loan Input Parameters'!$B$16,'Loan Input Parameters'!$B$24,IF(A33='Loan Input Parameters'!$B$16,'Loan Input Parameters'!$B$24+'Loan Input Parameters'!$B$20,0)) -> 7931.5631 | E33: =IF($A33<'Loan Input Parameters'!$B$16,C33*'Loan Input Parameters'!$B$15/12,"0.00") -> 3604.3493 | F33: =IF(A33<='Loan Input Parameters'!$B$16,'Loan Input Parameters'!$B$23,0) -> 69 | G33: =IF($A33<'Loan Input Parameters'!$B$16,D33-E33-F33,"0.00") -> 4258.2137 | H33: =IF($A33<'Loan Input Parameters'!$B$16,C33-G33,"0.00") -> 388943.53 | I33: =H33/'Loan Input Parameters'!$B$13 -> 0.77601299 | J33: =J32 -> 0.11 | K33: {=IF( AND(MONTH($B33)=1,SUMPRODUCT(--(MONTH($B$4:B33)=1))=1), K32*(1-22%*J33), IF( AND(MONTH($B33)=1,SUMPRODUCT(--(MONTH($B$4:B33)=1))=2), K32*(1-20%*J33), IF($A33<13,K32*(1-(J33*4%)), IF($A33<25,K32*(1-(J33*5%)),K32*(1-J33/12) ) ) ))} -> 332511.72 | L33: =IF(K33*'Loan Input Parameters'!$B$41<'Loan Input Parameters'!$B$42,'Loan Input Parameters'!$B$42,K33*'Loan Input Parameters'!$B$41) -> 0 | M33: =K33-L33 -> 332511.72 | N33: =H33-(K33-L33) -> 56431.809 | O33: =IF('Loan Input Parameters'!$B$8*3%<=4000,4000,IF('Loan Input Parameters'!$B$8*3%>=18000,18000,'Loan Input Parameters'!$B$8*3%)) -> 15000 | P33: =IF(N33<0,O33,N33+O33) -> 71431.809
A34: =A33+1 -> 31 | B34: =EOMONTH(B33,1) -> 46142 | C34: =IF(ROUND(H33,0)>0,H33,0) -> 388943.53 | D34: =IF(A34<'Loan Input Parameters'!$B$16,'Loan Input Parameters'!$B$24,IF(A34='Loan Input Parameters'!$B$16,'Loan Input Parameters'!$B$24+'Loan Input Parameters'!$B$20,0)) -> 7931.5631 | E34: =IF($A34<'Loan Input Parameters'!$B$16,C34*'Loan Input Parameters'!$B$15/12,"0.00") -> 3565.3157 | F34: =IF(A34<='Loan Input Parameters'!$B$16,'Loan Input Parameters'!$B$23,0) -> 69 | G34: =IF($A34<'Loan Input Parameters'!$B$16,D34-E34-F34,"0.00") -> 4297.2473 | H34: =IF($A34<'Loan Input Parameters'!$B$16,C34-G34,"0.00") -> 384646.28 | I34: =H34/'Loan Input Parameters'!$B$13 -> 0.7674392 | J34: =J33 -> 0.11 | K34: {=IF( AND(MONTH($B34)=1,SUMPRODUCT(--(MONTH($B$4:B34)=1))=1), K33*(1-22%*J34), IF( AND(MONTH($B34)=1,SUMPRODUCT(--(MONTH($B$4:B34)=1))=2), K33*(1-20%*J34), IF($A34<13,K33*(1-(J34*4%)), IF($A34<25,K33*(1-(J34*5%)),K33*(1-J34/12) ) ) ))} -> 329463.7 | L34: =IF(K34*'Loan Input Parameters'!$B$41<'Loan Input Parameters'!$B$42,'Loan Input Parameters'!$B$42,K34*'Loan Input Parameters'!$B$41) -> 0 | M34: =K34-L34 -> 329463.7 | N34: =H34-(K34-L34) -> 55182.585 | O34: =IF('Loan Input Parameters'!$B$8*3%<=4000,4000,IF('Loan Input Parameters'!$B$8*3%>=18000,18000,'Loan Input Parameters'!$B$8*3%)) -> 15000 | P34: =IF(N34<0,O34,N34+O34) -> 70182.585
A35: =A34+1 -> 32 | B35: =EOMONTH(B34,1) -> 46173 | C35: =IF(ROUND(H34,0)>0,H34,0) -> 384646.28 | D35: =IF(A35<'Loan Input Parameters'!$B$16,'Loan Input Parameters'!$B$24,IF(A35='Loan Input Parameters'!$B$16,'Loan Input Parameters'!$B$24+'Loan Input Parameters'!$B$20,0)) -> 7931.5631 | E35: =IF($A35<'Loan Input Parameters'!$B$16,C35*'Loan Input Parameters'!$B$15/12,"0.00") -> 3525.9243 | F35: =IF(A35<='Loan Input Parameters'!$B$16,'Loan Input Parameters'!$B$23,0) -> 69 | G35: =IF($A35<'Loan Input Parameters'!$B$16,D35-E35-F35,"0.00") -> 4336.6388 | H35: =IF($A35<'Loan Input Parameters'!$B$16,C35-G35,"0.00") -> 380309.65 | I35: =H35/'Loan Input Parameters'!$B$13 -> 0.75878682 | J35: =J34 -> 0.11 | K35: {=IF( AND(MONTH($B35)=1,SUMPRODUCT(--(MONTH($B$4:B35)=1))=1), K34*(1-22%*J35), IF( AND(MONTH($B35)=1,SUMPRODUCT(--(MONTH($B$4:B35)=1))=2), K34*(1-20%*J35), IF($A35<13,K34*(1-(J35*4%)), IF($A35<25,K34*(1-(J35*5%)),K34*(1-J35/12) ) ) ))} -> 326443.62 | L35: =IF(K35*'Loan Input Parameters'!$B$41<'Loan Input Parameters'!$B$42,'Loan Input Parameters'!$B$42,K35*'Loan Input Parameters'!$B$41) -> 0 | M35: =K35-L35 -> 326443.62 | N35: =H35-(K35-L35) -> 53866.031 | O35: =IF('Loan Input Parameters'!$B$8*3%<=4000,4000,IF('Loan Input Parameters'!$B$8*3%>=18000,18000,'Loan Input Parameters'!$B$8*3%)) -> 15000 | P35: =IF(N35<0,O35,N35+O35) -> 68866.031
A36: =A35+1 -> 33 | B36: =EOMONTH(B35,1) -> 46203 | C36: =IF(ROUND(H35,0)>0,H35,0) -> 380309.65 | D36: =IF(A36<'Loan Input Parameters'!$B$16,'Loan Input Parameters'!$B$24,IF(A36='Loan Input Parameters'!$B$16,'Loan Input Parameters'!$B$24+'Loan Input Parameters'!$B$20,0)) -> 7931.5631 | E36: =IF($A36<'Loan Input Parameters'!$B$16,C36*'Loan Input Parameters'!$B$15/12,"0.00") -> 3486.1718 | F36: =IF(A36<='Loan Input Parameters'!$B$16,'Loan Input Parameters'!$B$23,0) -> 69 | G36: =IF($A36<'Loan Input Parameters'!$B$16,D36-E36-F36,"0.00") -> 4376.3913 | H36: =IF($A36<'Loan Input Parameters'!$B$16,C36-G36,"0.00") -> 375933.25 | I36: =H36/'Loan Input Parameters'!$B$13 -> 0.75005513 | J36: =J35 -> 0.11 | K36: {=IF( AND(MONTH($B36)=1,SUMPRODUCT(--(MONTH($B$4:B36)=1))=1), K35*(1-22%*J36), IF( AND(MONTH($B36)=1,SUMPRODUCT(--(MONTH($B$4:B36)=1))=2), K35*(1-20%*J36), IF($A36<13,K35*(1-(J36*4%)), IF($A36<25,K35*(1-(J36*5%)),K35*(1-J36/12) ) ) ))} -> 323451.22 | L36: =IF(K36*'Loan Input Parameters'!$B$41<'Loan Input Parameters'!$B$42,'Loan Input Parameters'!$B$42,K36*'Loan Input Parameters'!$B$41) -> 0 | M36: =K36-L36 -> 323451.22 | N36: =H36-(K36-L36) -> 52482.039 | O36: =IF('Loan Input Parameters'!$B$8*3%<=4000,4000,IF('Loan Input Parameters'!$B$8*3%>=18000,18000,'Loan Input Parameters'!$B$8*3%)) -> 15000 | P36: =IF(N36<0,O36,N36+O36) -> 67482.039
A37: =A36+1 -> 34 | B37: =EOMONTH(B36,1) -> 46234 | C37: =IF(ROUND(H36,0)>0,H36,0) -> 375933.25 | D37: =IF(A37<'Loan Input Parameters'!$B$16,'Loan Input Parameters'!$B$24,IF(A37='Loan Input Parameters'!$B$16,'Loan Input Parameters'!$B$24+'Loan Input Parameters'!$B$20,0)) -> 7931.5631 | E37: =IF($A37<'Loan Input Parameters'!$B$16,C37*'Loan Input Parameters'!$B$15/12,"0.00") -> 3446.0548 | F37: =IF(A37<='Loan Input Parameters'!$B$16,'Loan Input Parameters'!$B$23,0) -> 69 | G37: =IF($A37<'Loan Input Parameters'!$B$16,D37-E37-F37,"0.00") -> 4416.5082 | H37: =IF($A37<'Loan Input Parameters'!$B$16,C37-G37,"0.00") -> 371516.75 | I37: =H37/'Loan Input Parameters'!$B$13 -> 0.74124339 | J37: =J36 -> 0.11 | K37: {=IF( AND(MONTH($B37)=1,SUMPRODUCT(--(MONTH($B$4:B37)=1))=1), K36*(1-22%*J37), IF( AND(MONTH($B37)=1,SUMPRODUCT(--(MONTH($B$4:B37)=1))=2), K36*(1-20%*J37), IF($A37<13,K36*(1-(J37*4%)), IF($A37<25,K36*(1-(J37*5%)),K36*(1-J37/12) ) ) ))} -> 320486.25 | L37: =IF(K37*'Loan Input Parameters'!$B$41<'Loan Input Parameters'!$B$42,'Loan Input Parameters'!$B$42,K37*'Loan Input Parameters'!$B$41) -> 0 | M37: =K37-L37 -> 320486.25 | N37: =H37-(K37-L37) -> 51030.5 | O37: =IF('Loan Input Parameters'!$B$8*3%<=4000,4000,IF('Loan Input Parameters'!$B$8*3%>=18000,18000,'Loan Input Parameters'!$B$8*3%)) -> 15000 | P37: =IF(N37<0,O37,N37+O37) -> 66030.5
A38: =A37+1 -> 35 | B38: =EOMONTH(B37,1) -> 46265 | C38: =IF(ROUND(H37,0)>0,H37,0) -> 371516.75 | D38: =IF(A38<'Loan Input Parameters'!$B$16,'Loan Input Parameters'!$B$24,IF(A38='Loan Input Parameters'!$B$16,'Loan Input Parameters'!$B$24+'Loan Input Parameters'!$B$20,0)) -> 7931.5631 | E38: =IF($A38<'Loan Input Parameters'!$B$16,C38*'Loan Input Parameters'!$B$15/12,"0.00") -> 3405.5702 | F38: =IF(A38<='Loan Input Parameters'!$B$16,'Loan Input Parameters'!$B$23,0) -> 69 | G38: =IF($A38<'Loan Input Parameters'!$B$16,D38-E38-F38,"0.00") -> 4456.9929 | H38: =IF($A38<'Loan Input Parameters'!$B$16,C38-G38,"0.00") -> 367059.75 | I38: =H38/'Loan Input Parameters'!$B$13 -> 0.73235088 | J38: =J37 -> 0.11 | K38: {=IF( AND(MONTH($B38)=1,SUMPRODUCT(--(MONTH($B$4:B38)=1))=1), K37*(1-22%*J38), IF( AND(MONTH($B38)=1,SUMPRODUCT(--(MONTH($B$4:B38)=1))=2), K37*(1-20%*J38), IF($A38<13,K37*(1-(J38*4%)), IF($A38<25,K37*(1-(J38*5%)),K37*(1-J38/12) ) ) ))} -> 317548.46 | L38: =IF(K38*'Loan Input Parameters'!$B$41<'Loan Input Parameters'!$B$42,'Loan Input Parameters'!$B$42,K38*'Loan Input Parameters'!$B$41) -> 0 | M38: =K38-L38 -> 317548.46 | N38: =H38-(K38-L38) -> 49511.298 | O38: =IF('Loan Input Parameters'!$B$8*3%<=4000,4000,IF('Loan Input Parameters'!$B$8*3%>=18000,18000,'Loan Input Parameters'!$B$8*3%)) -> 15000 | P38: =IF(N38<0,O38,N38+O38) -> 64511.298
